---
title: 错误处理机制:异常|断言|日志
date: 2019-09-06 12:00:00
tags:
  - Java核心卷
  - 错误处理
---

### 异常

#### Exception与Error

![img](https://www.runoob.com/wp-content/uploads/2013/12/12-130Q1234I6223.jpg)

Error和Exception都派生于Throwable，Error描述了 Java 运行时系统的内部错误和资源耗尽错误，出现了Error抛出来也没有用，只能终止程序。

#### 再次抛出异常

再次抛出异常有两种方式，第一种方式是使用异常的构造器

```java
try
{
    
}
catch(SQLException e)
{
    thorw new ServletException("database error:" + e.getMessage());
}
```

第二种方式是使用initCause和getCause方法。因为在程序开发中，项目越到底层抛出的异常类型会越多，导致上层需要很多catch来捕获异常，为了避免这样，可以在捕获异常后，将多种异常统一成一个异常再抛出，需要注意的问题是统一的那个异常会丢失原异常的信息，所以使用initCause方法，将原异常进行包装，再使用getCause可以获取原异常。

```java
try
{

}
catch(SQLException e)
{
	Throwable se = new ServletException("database error");
    se.initCause(e);//包装原异常给更大的异常，减少异常种类和上层catch数量。
    throw se;
}

//Thorwable e = se.getCause();获取原异常
```

#### finally

try-catch-finally按顺序执行，其中可以没有catch部分，只有try-finally部分。也可以有多个catch，捕获多个异常类型。

不管是否有异常被catch到，finally都会执行，finally中一般进行资源的释放、关闭数据库的连接等操作。

try、catch中有返回值，而try中抛出的异常恰好与catch中的异常匹配，则返回catch中的return值。

如果finally块中有return，则返回finally的返回值，不返回try或catch中的返回值。

如果finally块中抛出异常，则整个try、catch、finally块中抛出异常，并且没有返回值。所以推荐如下的嵌套写法。

```java
InputStream in = ...;
try{
    try{
        ...
    }
    finally{
        in.close();
    }
}
catch(IOException e)
{
    
}
```

### 断言

断言机制允许在测试期间向代码中插入一些检查语句，当代码发布时，这些插入的断言语句会自动地被移走。

断言的语法为

```java
assert 条件；
assert 条件:表达式；
```

这两种方式都会对条件进行检测，如果结果为false，则抛出一个AssertionError异常。在第二种形式中，表达式会传入AssertionError的构造器来构造异常。

例如判断x是否是大于等于0

```java
assert x >= 0;
assert x>=0:x;
```